Workbook

Sheet Raw Data
A1: Date | B1: Cost
A2: 45936
A3: 45937
A4: 45938
A5: 45939
A6: 45940
A7: 45941
A8: 45942
A9: 45943
A10: 45944
A11: 45945
A12: 45946
A13: 45947
... A271: 46205
A272: 46206 | B272: 450000
A273: 46207
A274: 46208
A275: 46209
A276: 46210
A277: 46211
A278: 46212
A279: 46213
A280: 46214
A281: 46215
A282: 46216
A283: 46217
A284: 46218
... A301: 46235
A302: 46236 | B302: 50000
A303: 46237
A304: 46238
A305: 46239
A306: 46240
A307: 46241
A308: 46242
A309: 46243
A310: 46244
A311: 46245
A312: 46246
A313: 46247
...

Sheet Graph
A1: Date | B1: Cost | C1: Cumulative Cost
A2: =IF('Raw Data'!A2=0, #N/A,'Raw Data'!A2) | B2: ='Raw Data'!B2 | C2: =Table1[[#This Row],[Cost]]
A3: =IF('Raw Data'!A3=0, #N/A,'Raw Data'!A3) | B3: ='Raw Data'!B3 | C3: =SUM($B$2:B3)
A4: =IF('Raw Data'!A4=0, #N/A,'Raw Data'!A4) | B4: ='Raw Data'!B4 | C4: =SUM($B$2:B4)
A5: =IF('Raw Data'!A5=0, #N/A,'Raw Data'!A5) | B5: ='Raw Data'!B5 | C5: =SUM($B$2:B5)
A6: =IF('Raw Data'!A6=0, #N/A,'Raw Data'!A6) | B6: ='Raw Data'!B6 | C6: =SUM($B$2:B6)
A7: =IF('Raw Data'!A7=0, #N/A,'Raw Data'!A7) | B7: ='Raw Data'!B7 | C7: =SUM($B$2:B7)
A8: =IF('Raw Data'!A8=0, #N/A,'Raw Data'!A8) | B8: ='Raw Data'!B8 | C8: =SUM($B$2:B8)
A9: =IF('Raw Data'!A9=0, #N/A,'Raw Data'!A9) | B9: ='Raw Data'!B9 | C9: =SUM($B$2:B9)
A10: =IF('Raw Data'!A10=0, #N/A,'Raw Data'!A10) | B10: ='Raw Data'!B10 | C10: =SUM($B$2:B10)
A11: =IF('Raw Data'!A11=0, #N/A,'Raw Data'!A11) | B11: ='Raw Data'!B11 | C11: =SUM($B$2:B11)
A12: =IF('Raw Data'!A12=0, #N/A,'Raw Data'!A12) | B12: ='Raw Data'!B12 | C12: =SUM($B$2:B12)
A13: =IF('Raw Data'!A13=0, #N/A,'Raw Data'!A13) | B13: ='Raw Data'!B13 | C13: =SUM($B$2:B13)
A14: =IF('Raw Data'!A14=0, #N/A,'Raw Data'!A14) | B14: ='Raw Data'!B14 | C14: =SUM($B$2:B14)
... A733: =IF('Raw Data'!A733=0, #N/A,'Raw Data'!A733) | B733: ='Raw Data'!B733 | C733: =SUM($B$2:B733)
